Workbook

Sheet Fortune500
A1: Company_Name | B1: Ticker | C1: Avg_PURPOSE | D1: Avg_PHYGITAL | E1: Avg_PLATFORMS | F1: Avg_PARTICIPATION | G1: Avg_PARTNERSHIPS | H1: Avg_PEOPLE | I1: Avg_AI_Intensity
A2: 3M | B2: MMM | C2: 3.3675 | D2: 0 | E2: 0.89 | F2: 0 | G2: 0.3875 | H2: 0.8225 | I2: =VLOOKUP(B2,Data!B:K,10,FALSE) -> 0.6563
A3: A-Mark Precious Metals | B3: AMRK | C3: 5.3866667 | D3: 0 | E3: 4.2633333 | F3: 0 | G3: 6.0366667 | H3: 6.2366667 | I3: =VLOOKUP(B3,Data!B:K,10,FALSE) -> #N/A
A4: ABM Industries | B4: ABM | C4: 6.5366667 | D4: 0 | E4: 0.47666667 | F4: 0 | G4: 8.53 | H4: 23.21 | I4: =VLOOKUP(B4,Data!B:K,10,FALSE) -> 0.6582
A5: AECOM | B5: ACM | C5: 3.1566667 | D5: 0 | E5: 2.47 | F5: 0 | G5: 33.75 | H5: 13.246667 | I5: =VLOOKUP(B5,Data!B:K,10,FALSE) -> 0.5554
A6: AES | B6: AES | C6: 0.76 | D6: 0 | E6: 2.0466667 | F6: 3.8866667 | G6: 7.2 | H6: 2.4433333 | I6: =VLOOKUP(B6,Data!B:K,10,FALSE) -> 0.6606
A7: AGCO | B7: AGCO | C7: 4.9775 | D7: 0 | E7: 1.135 | F7: 2.935 | G7: 35.2725 | H7: 9.96 | I7: =VLOOKUP(B7,Data!B:K,10,FALSE) -> 0.566
A8: APA | B8: APA | C8: 4.98 | D8: 0 | E8: 1.12 | F8: 0 | G8: 5.355 | H8: 13.91 | I8: =VLOOKUP(B8,Data!B:K,10,FALSE) -> 0.6562
A9: ARKO | B9: ARKO | C9: 3.02 | D9: 0 | E9: 2.7725 | F9: 0 | G9: 0 | H9: 0.8825 | I9: =VLOOKUP(B9,Data!B:K,10,FALSE) -> 0.6443
A10: AT&T | B10: T | C10: 5.775 | D10: 11.2075 | E10: 2.4575 | F10: 31.6675 | G10: 1.75 | H10: 6.365 | I10: =VLOOKUP(B10,Data!B:K,10,FALSE) -> 0.6981
A11: AbbVie | B11: ABBV | C11: 2.55 | D11: 0 | E11: 1.2 | F11: 0 | G11: 18.905 | H11: 8.79 | I11: =VLOOKUP(B11,Data!B:K,10,FALSE) -> 0.6096
A12: Abbott Laboratories | B12: ABT | C12: 4.295 | D12: 0 | E12: 3.5825 | F12: 0 | G12: 1.0425 | H12: 3.7575 | I12: =VLOOKUP(B12,Data!B:K,10,FALSE) -> 0.6127
A13: Adobe | B13: ADBE | C13: 1.5775 | D13: 3.155 | E13: 13.395 | F13: 7.06 | G13: 4.1775 | H13: 22.495 | I13: =VLOOKUP(B13,Data!B:K,10,FALSE) -> 0.734
... A469: Zoetis | B469: ZTS | C469: 5.875 | D469: 0 | E469: 1.535 | F469: 0 | G469: 2.7325 | H469: 3.215 | I469: =VLOOKUP(B469,Data!B:K,10,FALSE) -> 0.6283

Sheet Data
A1: company_name | B1: ticker | C1: cik | D1: universal_name | E1: country_forbes | F1: industry_forbes | G1: rank_forbes | H1: rank_fortune | I1: market_cap_yf | J1: company_profile | K1: ai_score_v2_avg | L1: ai_score_v2_min | M1: ai_score_v2_max | N1: filing_count
A2: Autodesk | B2: ADSK | C2: 769397 | D2: Autodesk | E2: United States | F2: IT Software & Services | G2: 1114 | I2: 46212481024 | J2: hybrid | K2: 0.8026 | L2: 0.8008 | M2: 0.8064 | N2: 16
A3: CoreWeave | B3: CRWV | C3: 1769628 | D3: CoreWeave | E3: United States | F3: IT Software & Services | G3: 1799 | I3: 47267246080 | J3: hybrid | K3: 0.8003 | L3: 0.8003 | M3: 0.8003 | N3: 3
A4: ZIM Integrated Shipping Services | B4: ZIM | C4: 1654126 | D4: ZIM Integrated Shipping Services | E4: Israel | F4: Transportation | G4: 1403 | I4: 3467971840 | J4: buyer | K4: 0.7941 | L4: 0.7555 | M4: 0.8072 | N4: 4
A5: Snowflake | B5: SNOW | C5: 1640147 | D5: Snowflake | E5: United States | F5: IT Software & Services | G5: 1619 | I5: 54352994304 | J5: hybrid | K5: 0.7803 | L5: 0.75 | M5: 0.8087 | N5: 16
A6: Roblox | B6: RBLX | C6: 1315098 | D6: Roblox | E6: United States | F6: IT Software & Services | G6: 1652 | I6: 43826380800 | J6: hybrid | K6: 0.7763 | L6: 0.75 | M6: 0.8051 | N6: 16
A7: AstraZeneca | B7: AZN | C7: 901832 | D7: AstraZeneca | E7: United Kingdom | F7: Drugs & Biotechnology | G7: 109 | I7: 318490247168 | J7: buyer | K7: 0.775 | L7: 0.75 | M7: 0.8 | N7: 4
A8: Microsoft | B8: MSFT | C8: 789019 | D8: Microsoft | E8: United States | F8: IT Software & Services | G8: 9 | H8: 14 | I8: 3048369291264 | J8: hybrid | K8: 0.7649 | L8: 0.75 | M8: 0.8105 | N8: 16
A9: JD.com | B9: JD | C9: 1549802 | D9: JD.com | E9: China | F9: Retailing | G9: 171 | I9: 40204816384 | J9: hybrid | K9: 0.7636 | L9: 0.763 | M9: 0.7645 | N9: 4
A10: Nu Holdings | B10: NU | C10: 1691493 | D10: Nu Holdings | E10: Cayman Islands | F10: Banking | G10: 546 | I10: 80388104192 | J10: buyer | K10: 0.7617 | L10: 0.7596 | M10: 0.7637 | N10: 4
A11: Bid | B11: BIDU | C11: 1329099 | D11: Baidu | E11: China | F11: IT Software & Services | G11: 403 | I11: 47117533184 | J11: hybrid | K11: 0.7572 | L11: 0.7538 | M11: 0.7605 | N11: 16
A12: FactSet Research Systems | B12: FDS | C12: 1013237 | D12: FactSet Research Systems | E12: United States | F12: Business Services & Supplies | G12: 1863 | I12: 7210073088 | J12: buyer | K12: 0.757 | L12: 0.75 | M12: 0.8044 | N12: 16
A13: Alibaba Group | B13: BABA | C13: 1577552 | D13: Alibaba Group | E13: China | F13: Retailing | G13: 33 | I13: 390184304640 | J13: hybrid | K13: 0.7565 | L13: 0.7 | M13: 0.8089 | N13: 4
A14: Dell Technologies | B14: DELL | C14: 1571996 | D14: Dell Technologies | E14: United States | F14: Technology Hardware & Equipment | G14: 183 | H14: 44 | I14: 81020502016 | J14: hybrid | K14: 0.7541 | L14: 0.75 | M14: 0.768 | N14: 16
A15: Check Point Software | B15: CHKP | C15: 1015922 | D15: Check Point Software | E15: Israel | F15: IT Software & Services | G15: 1386 | I15: 16655010816 | J15: hybrid | K15: 0.7534 | L15: 0.7513 | M15: 0.7554 | N15: 4
A16: PDD Holdings | B16: PDD | C16: 1737806 | D16: PDD Holdings | E16: Ireland | F16: Retailing | G16: 152 | I16: 151632429056 | J16: hybrid | K16: 0.7527 | L16: 0.7523 | M16: 0.753 | N16: 4
A17: Palo Alto Networks | B17: PANW | C17: 1327567 | D17: Palo Alto Networks | E17: United States | F17: IT Software & Services | G17: 761 | H17: 470 | I17: 117009268736 | J17: hybrid | K17: 0.7526 | L17: 0.75 | M17: 0.7633 | N17: 16
A18: Elbit Systems | B18: ESLT | C18: 1027664 | D18: Elbit Systems | E18: Israel | F18: Aerospace & Defense | G18: 1947 | I18: 34992005120 | J18: hybrid | K18: 0.7522 | L18: 0.751 | M18: 0.753 | N18: 4
A19: XP | B19: XP | C19: 1787425 | D19: XP | E19: Brazil | F19: Diversified Financials | G19: 1261 | I19: 11432478720 | J19: buyer | K19: 0.7518 | L19: 0.7515 | M19: 0.7524 | N19: 4
A20: Palantir Technologies | B20: PLTR | C20: 1321655 | D20: Palantir Technologies | E20: United States | F20: IT Software & Services | G20: 1347 | I20: 307747127296 | J20: hybrid | K20: 0.7514 | L20: 0.7 | M20: 0.8086 | N20: 16
A21: Zscaler | B21: ZS | C21: 1713683 | D21: Zscaler | E21: United States | F21: Business Services & Supplies | G21: 1746 | I21: 23139272704 | J21: hybrid | K21: 0.7514 | L21: 0.75 | M21: 0.7592 | N21: 16
A22: Datadog | B22: DDOG | C22: 1561550 | D22: Datadog | E22: United States | F22: IT Software & Services | G22: 1726 | I22: 37211426816 | J22: hybrid | K22: 0.7514 | L22: 0.75 | M22: 0.7574 | N22: 16
A23: CrowdStrike | B23: CRWD | C23: 1535527 | D23: CrowdStrike | E23: United States | F23: IT Software & Services | G23: 1490 | I23: 88746213376 | J23: hybrid | K23: 0.7513 | L23: 0.75 | M23: 0.7563 | N23: 16
A24: DocuSign | B24: DOCU | C24: 1261333 | D24: DocuSign | E24: United States | F24: IT Software & Services | G24: 1415 | I24: 8152101888 | J24: hybrid | K24: 0.7509 | L24: 0.75 | M24: 0.7538 | N24: 16
A25: Cloudflare | B25: NET | C25: 1477333 | D25: Cloudflare | E25: United States | F25: IT Software & Services | G25: 1671 | I25: 58209148928 | J25: hybrid | K25: 0.7507 | L25: 0.75 | M25: 0.7547 | N25: 16
A26: Lumen Technologies | B26: LUMN | C26: 18926 | D26: Lumen Technologies | E26: United States | F26: Telecommunications Services | G26: 1441 | H26: 325 | I26: 7608835072 | J26: hybrid | K26: 0.7506 | L26: 0.75 | M26: 0.7529 | N26: 16
A27: DoorDash | B27: DASH | C27: 1792789 | D27: DoorDash | E27: United States | F27: Transportation | G27: 1191 | H27: 394 | I27: 71157858304 | J27: hybrid | K27: 0.7506 | L27: 0.75 | M27: 0.7525 | N27: 16
A28: Deutsche Bank | B28: DB | C28: 1159508 | D28: Deutsche Bank | E28: Germany | F28: Diversified Financials | G28: 133 | I28: 69268037632 | J28: buyer | K28: 0.7506 | L28: 0.75 | M28: 0.7512 | N28: 4
A29: Copart | B29: CPRT | C29: 900075 | D29: Copart | E29: United States | F29: Retailing | G29: 1062 | I29: 34519511040 | J29: buyer | K29: 0.7503 | L29: 0.75 | M29: 0.7521 | N29: 16
A30: Shinhan Financial Group | B30: SHG | C30: 1263043 | D30: Shinhan Financial Group | E30: South Korea | F30: Banking | G30: 308 | J30: buyer | K30: 0.75 | L30: 0.75 | M30: 0.75 | N30: 4
A31: HubSpot | B31: HUBS | C31: 1404655 | D31: HubSpot | E31: United States | F31: IT Software & Services | G31: 1762 | I31: 11707872256 | J31: hybrid | K31: 0.7473 | L31: 0.7 | M31: 0.8004 | N31: 16
A32: AppLovin | B32: APP | C32: 1751008 | D32: AppLovin | E32: United States | F32: IT Software & Services | G32: 1007 | I32: 128452370432 | J32: hybrid | K32: 0.7442 | L32: 0.7 | M32: 0.8006 | N32: 16
A33: Wipro | B33: WIT | C33: 1123799 | D33: Wipro | E33: India | F33: IT Software & Services | G33: 901 | I33: 23401965568 | J33: buyer | K33: 0.7432 | L33: 0.7026 | M33: 0.7592 | N33: 4
A34: Sirius XM | B34: SIRI | C34: 908937 | D34: Sirius XM | E34: United States | F34: Media | G34: 1822 | H34: 448 | I34: 7030772224 | J34: hybrid | K34: 0.7422 | L34: 0.7 | M34: 0.7583 | N34: 16
A35: Synopsys | B35: SNPS | C35: 883241 | D35: Synopsys | E35: United States | F35: IT Software & Services | G35: 970 | I35: 80208240640 | J35: hybrid | K35: 0.7419 | L35: 0.7 | M35: 0.7556 | N35: 16
A36: Block | B36: XYZ | C36: 1512673 | D36: Block | E36: United States | F36: Banking | G36: 434 | H36: 179 | I36: 30695602176 | J36: hybrid | K36: 0.7389 | L36: 0.7 | M36: 0.756 | N36: 16
A37: Atlassian | B37: TEAM | C37: 1650372 | D37: Atlassian | E37: United States | F37: IT Software & Services | G37: 1588 | I37: 18715279360 | J37: hybrid | K37: 0.7379 | L37: 0.7 | M37: 0.8004 | N37: 14
A38: Fortinet | B38: FTNT | C38: 1262039 | D38: Fortinet | E38: United States | F38: IT Software & Services | G38: 1003 | I38: 58190245888 | J38: hybrid | K38: 0.7364 | L38: 0.7 | M38: 0.8092 | N38: 16
A39: Axon Enterprise | B39: AXON | C39: 1069183 | D39: Axon Enterprise | E39: United States | F39: Aerospace & Defense | G39: 1646 | I39: 33687754752 | J39: hybrid | K39: 0.7355 | L39: 0.7 | M39: 0.8015 | N39: 16
A40: Adobe | B40: ADBE | C40: 796343 | D40: Adobe | E40: United States | F40: IT Software & Services | G40: 340 | H40: 201 | I40: 103203733504 | J40: hybrid | K40: 0.734 | L40: 0.7 | M40: 0.7755 | N40: 16
...
